Workbook

Sheet Thai Stock
A1: Name | B1: Purchase price | C1: Quantity | D1: Cost | E1: Current Price | F1: Current Value | G1: Profit | H1: Percent | J1: Net Cost | K1: Net Current Value | L1: Net Profit | M1: Net Percent
A2: SCB | B2: 98.5 | C2: 100 | D2: =B2*C2 -> 9850 | E2: =THAISTOCK(A2) -> 134.5 | F2: =C2*E2 -> 13450 | G2: =F2-D2 -> 3600 | H2: =ROUND(100*F2/D2,2)-100 -> 36.55 | J2: =SUM(D:D) -> 28800 | K2: =SUM(F:F) -> 35525 | L2: =SUM(G:G) -> 6725 | M2: =ROUND(100*K2/J2,2)-100 -> 23.35
A3: SCB | B3: 117.5 | C3: 100 | D3: =B3*C3 -> 11750 | E3: =THAISTOCK(A3) -> 134.5 | F3: =C3*E3 -> 13450 | G3: =F3-D3 -> 1700 | H3: =ROUND(100*F3/D3,2)-100 -> 14.47
A4: KKP | B4: 72 | C4: 100 | D4: =B4*C4 -> 7200 | E4: =THAISTOCK(A4) -> 86.25 | F4: =C4*E4 -> 8625 | G4: =F4-D4 -> 1425 | H4: =ROUND(100*F4/D4,2)-100 -> 19.79
J5: Name | K5: Cost | L5: Current Value | M5: Sector | N5: Percent
J6: SCB | K6: =SUMIF(A:A,J6,D:D) -> 21600 | L6: =SUMIF(A:A,J6,F:F) -> 26900 | M6: Financials | N6: =ROUND(100*THAI_STOCK_SUMMARIZE[Current Value]/THAI_STOCK_SUMMARIZE[Cost],2)-100 -> 24.54
J7: KKP | K7: =SUMIF(A:A,J7,D:D) -> 7200 | L7: =SUMIF(A:A,J7,F:F) -> 8625 | M7: Financials | N7: =ROUND(100*THAI_STOCK_SUMMARIZE[Current Value]/THAI_STOCK_SUMMARIZE[Cost],2)-100 -> 19.79
J10: Sector | K10: Cost | L10: Profit | M10: Percent
J11: Financials | K11: =SUMIF(THAI_STOCK_SUMMARIZE[Sector],J11,THAI_STOCK_SUMMARIZE[Cost]) -> 28800 | L11: =SUMIF(THAI_STOCK_SUMMARIZE[Sector],J11,THAI_STOCK_SUMMARIZE[Current Value]) -> 35525 | M11: =ROUND((100*L11/K11),2)-100 -> 23.35

Sheet Fund
A1: Name | B1: Purchase price | C1: Quantity | D1: Cost | E1: Current Price | F1: Current Value | G1: Profit | H1: Percent | J1: Net Cost | K1: Net Current Value | L1: Net Profit | M1: Net Percent
A2: ES-GTECH | B2: 20.3208 | C2: 98.4213 | D2: =B2*C2 -> 1999.9996 | E2: =setMutualfundInfo(A2) -> 38.8677 | F2: =C2*E2 -> 3825.4096 | G2: =F2-D2 -> 1825.41 | H2: =ROUND((100*F2)/D2,2)-100 -> 91.27 | J2: =SUM(D:D) -> 37162.443 | K2: =SUM(F:F) -> 45957.767 | L2: =SUM(G:G) -> 8795.3246 | M2: =ROUND(100*K2/J2,2)-100 -> 23.67
A3: ASP-S&P500-A | B3: 57.7668 | C3: 86.5549 | D3: =B3*C3 -> 4999.9996 | E3: =setMutualfundInfo(A3) -> 69.8739 | F3: =C3*E3 -> 6047.9284 | G3: =F3-D3 -> 1047.9288 | H3: =ROUND((100*F3)/D3,2)-100 -> 20.96
A4: ASP-S&P500-A | B4: 56.3612 | C4: 88.7135 | D4: =B4*C4 -> 4999.9993 | E4: =setMutualfundInfo(A4) -> 69.8739 | F4: =C4*E4 -> 6198.7582 | G4: =F4-D4 -> 1198.7589 | H4: =ROUND((100*F4)/D4,2)-100 -> 23.98
A5: DAOL-KOREAEQ | B5: 14.5769 | C5: 102.9025 | D5: =B5*C5 -> 1499.9995 | E5: =setMutualfundInfo(A5) -> 23.2316 | F5: =C5*E5 -> 2390.5897 | G5: =F5-D5 -> 890.59027 | H5: =ROUND((100*F5)/D5,2)-100 -> 59.37 | J5: Name | K5: Cost | L5: Current Value | M5: Sector | N5: Percent
A6: TEMxCH | B6: 12.9019 | C6: 155.0159 | D6: =B6*C6 -> 1999.9996 | E6: =setMutualfundInfo(A6) -> 16.5984 | F6: =C6*E6 -> 2573.0159 | G6: =F6-D6 -> 573.01627 | H6: =ROUND((100*F6)/D6,2)-100 -> 28.65 | J6: ES-GTECH | K6: =SUMIF(A:A,J6,D:D) -> 3999.9995 | L6: =SUMIF(A:A,J6,F:F) -> 6100.8825 | M6: Technology | N6: =ROUND((100*L6/K6),2)-100 -> 52.52
A7: DAOL-DEFENSE | B7: 17.0716 | C7: 146.442 | D7: =B7*C7 -> 2499.9992 | E7: =setMutualfundInfo(A7) -> 14.5998 | F7: =C7*E7 -> 2138.0239 | G7: =F7-D7 -> -361.97534 | H7: =ROUND((100*F7)/D7,2)-100 -> -14.48 | J7: ASP-S&P500-A | K7: =SUMIF(A:A,J7,D:D) -> 9999.9989 | L7: =SUMIF(A:A,J7,F:F) -> 12246.687 | M7: S&P | N7: =ROUND((100*L7/K7),2)-100 -> 22.47
A8: K-GOLD-A(A) | B8: 27.0606 | C8: 15.1497 | D8: =B8*C8 -> 409.95997 | E8: =setMutualfundInfo(A8) -> 23.0761 | F8: =C8*E8 -> 349.59599 | G8: =F8-D8 -> -60.36398 | H8: =ROUND((100*F8)/D8,2)-100 -> -14.72 | J8: DAOL-KOREAEQ | K8: =SUMIF(A:A,J8,D:D) -> 1499.9995 | L8: =SUMIF(A:A,J8,F:F) -> 2390.5897 | M8: Korea | N8: =ROUND((100*L8/K8),2)-100 -> 59.37
A9: ONE-RAREEARTH | B9: 11.9095 | C9: 251.8997 | D9: =B9*C9 -> 2999.9995 | E9: =setMutualfundInfo(A9) -> 12.7513 | F9: =C9*E9 -> 3212.0486 | G9: =F9-D9 -> 212.04917 | H9: =ROUND((100*F9)/D9,2)-100 -> 7.07 | J9: TEMxCH | K9: =SUMIF(A:A,J9,D:D) -> 1999.9996 | L9: =SUMIF(A:A,J9,F:F) -> 2573.0159 | M9: Asia | N9: =ROUND((100*L9/K9),2)-100 -> 28.65
A10: A-GRID | B10: 10.3026 | C10: 252.3239 | D10: =B10*C10 -> 2599.5922 | E10: =setMutualfundInfo(A10) -> 11.0288 | F10: =C10*E10 -> 2782.8299 | G10: =F10-D10 -> 183.23762 | H10: =ROUND((100*F10)/D10,2)-100 -> 7.05 | J10: DAOL-DEFENSE | K10: =SUMIF(A:A,J10,D:D) -> 2499.9992 | L10: =SUMIF(A:A,J10,F:F) -> 2138.0239 | M10: Defense | N10: =ROUND((100*L10/K10),2)-100 -> -14.48
A11: PRINCIPAL GCLOUD-A | B11: 4.8327 | C11: 310.3855 | D11: =B11*C11 -> 1500 | E11: =setMutualfundInfo(A11) -> 4.8266 | F11: =C11*E11 -> 1498.1066 | G11: =F11-D11 -> -1.8933515 | H11: =ROUND((100*F11)/D11,2)-100 -> -0.13 | J11: K-GOLD-A(A) | K11: =SUMIF(A:A,J11,D:D) -> 409.95997 | L11: =SUMIF(A:A,J11,F:F) -> 349.59599 | M11: Gold | N11: =ROUND((100*L11/K11),2)-100 -> -14.72
A12: TLNDQINCOME-UH-X | B12: 10.0713 | C12: 248.2301 | D12: =B12*C12 -> 2499.9998 | E12: =setMutualfundInfo(A12) -> 10.8216 | F12: =C12*E12 -> 2686.2468 | G12: =F12-D12 -> 186.24704 | H12: =ROUND((100*F12)/D12,2)-100 -> 7.45 | J12: ONE-RAREEARTH | K12: =SUMIF(A:A,J12,D:D) -> 2999.9995 | L12: =SUMIF(A:A,J12,F:F) -> 3212.0486 | M12: RareEarth | N12: =ROUND((100*L12/K12),2)-100 -> 7.07
A13: SCBSEMI(A) | B13: 23.5158 | C13: 224.4798 | D13: =B13*C13 -> 5278.8221 | E13: =setMutualfundInfo(A13) -> 36.6259 | F13: =C13*E13 -> 8221.7747 | G13: =F13-D13 -> 2942.9526 | H13: =ROUND((100*F13)/D13,2)-100 -> 55.75 | J13: A-GRID | K13: =SUMIF(A:A,J13,D:D) -> 2599.5922 | L13: =SUMIF(A:A,J13,F:F) -> 2782.8299 | M13: Foundation | N13: =ROUND((100*L13/K13),2)-100 -> 7.05
A14: ES-GTECH | B14: 31.7664 | C14: 31.4798 | D14: =B14*C14 -> 999.99992 | E14: =setMutualfundInfo(A14) -> 38.8677 | F14: =C14*E14 -> 1223.5474 | G14: =F14-D14 -> 223.5475 | H14: =ROUND((100*F14)/D14,2)-100 -> 22.35 | J14: PRINCIPAL GCLOUD-A | K14: =SUMIF(A:A,J14,D:D) -> 1500 | L14: =SUMIF(A:A,J14,F:F) -> 1498.1066 | M14: Technology | N14: =ROUND((100*L14/K14),2)-100 -> -0.13
A15: A-SLVP | B15: 11.7926 | C15: =79.4596742153*2 -> 158.91935 | D15: =B15*C15 -> 1874.0723 | E15: =setMutualfundInfo(A15) -> 11.062 | F15: =C15*E15 -> 1757.9658 | G15: =F15-D15 -> -116.10648 | H15: =ROUND((100*F15)/D15,2)-100 -> -6.2 | J15: TLNDQINCOME-UH-X | K15: =SUMIF(A:A,J15,D:D) -> 2499.9998 | L15: =SUMIF(A:A,J15,F:F) -> 2686.2468 | M15: Technology | N15: =ROUND((100*L15/K15),2)-100 -> 7.45
A16: ES-GTECH | B16: 36.9491 | C16: 27.064259 | D16: =B16*C16 -> 1000 | E16: =setMutualfundInfo(A16) -> 38.8677 | F16: =C16*E16 -> 1051.9255 | G16: =F16-D16 -> 51.925487 | H16: =ROUND((100*F16)/D16,2)-100 -> 5.19 | J16: A-SLVP | K16: =SUMIF(A:A,J16,D:D) -> 1874.0723 | L16: =SUMIF(A:A,J16,F:F) -> 1757.9658 | M16: Silver | N16: =ROUND((100*L16/K16),2)-100 -> -6.2
J21: Sector | K21: Cost | L21: Profit | M21: Percent
J22: Technology | K22: =SUMIF(FUND_SUMMARIZE[Sector],J22,FUND_SUMMARIZE[Cost]) -> 7999.9993 | L22: =SUMIF(FUND_SUMMARIZE[Sector],J22,FUND_SUMMARIZE[Current Value]) -> 10285.236 | M22: =ROUND((100*L22/K22),2)-100 -> 28.57
J23: S&P | K23: =SUMIF(FUND_SUMMARIZE[Sector],J23,FUND_SUMMARIZE[Cost]) -> 9999.9989 | L23: =SUMIF(FUND_SUMMARIZE[Sector],J23,FUND_SUMMARIZE[Current Value]) -> 12246.687 | M23: =ROUND((100*L23/K23),2)-100 -> 22.47
J24: Korea | K24: =SUMIF(FUND_SUMMARIZE[Sector],J24,FUND_SUMMARIZE[Cost]) -> 1499.9995 | L24: =SUMIF(FUND_SUMMARIZE[Sector],J24,FUND_SUMMARIZE[Current Value]) -> 2390.5897 | M24: =ROUND((100*L24/K24),2)-100 -> 59.37
J25: Asia | K25: =SUMIF(FUND_SUMMARIZE[Sector],J25,FUND_SUMMARIZE[Cost]) -> 1999.9996 | L25: =SUMIF(FUND_SUMMARIZE[Sector],J25,FUND_SUMMARIZE[Current Value]) -> 2573.0159 | M25: =ROUND((100*L25/K25),2)-100 -> 28.65
J26: Defense | K26: =SUMIF(FUND_SUMMARIZE[Sector],J26,FUND_SUMMARIZE[Cost]) -> 2499.9992 | L26: =SUMIF(FUND_SUMMARIZE[Sector],J26,FUND_SUMMARIZE[Current Value]) -> 2138.0239 | M26: =ROUND((100*L26/K26),2)-100 -> -14.48
J27: Gold | K27: =SUMIF(FUND_SUMMARIZE[Sector],J27,FUND_SUMMARIZE[Cost]) -> 409.95997 | L27: =SUMIF(FUND_SUMMARIZE[Sector],J27,FUND_SUMMARIZE[Current Value]) -> 349.59599 | M27: =ROUND((100*L27/K27),2)-100 -> -14.72
J28: RareEarth | K28: =SUMIF(FUND_SUMMARIZE[Sector],J28,FUND_SUMMARIZE[Cost]) -> 2999.9995 | L28: =SUMIF(FUND_SUMMARIZE[Sector],J28,FUND_SUMMARIZE[Current Value]) -> 3212.0486 | M28: =ROUND((100*L28/K28),2)-100 -> 7.07
J29: Foundation | K29: =SUMIF(FUND_SUMMARIZE[Sector],J29,FUND_SUMMARIZE[Cost]) -> 2599.5922 | L29: =SUMIF(FUND_SUMMARIZE[Sector],J29,FUND_SUMMARIZE[Current Value]) -> 2782.8299 | M29: =ROUND((100*L29/K29),2)-100 -> 7.05
J30: Silver | K30: =SUMIF(FUND_SUMMARIZE[Sector],J30,FUND_SUMMARIZE[Cost]) -> 1874.0723 | L30: =SUMIF(FUND_SUMMARIZE[Sector],J30,FUND_SUMMARIZE[Current Value]) -> 1757.9658 | M30: =ROUND((100*L30/K30),2)-100 -> -6.2

Sheet USA Stock
A1: Name | B1: Purchase price | C1: Quantity | D1: Cost | E1: Current Price | F1: Current Value | G1: Profit | H1: Percent | J1: Net Cost | K1: Net Current Value | L1: Net Profit | M1: Net Percent
A2: AAPL | B2: 182.13 | C2: 0.3145555 | D2: =B2*C2 -> 57.289993 | E2: =IFERROR(__xludf.DUMMYFUNCTION("GOOGLEFINANCE(A2)"),312.51) -> 312.51 | F2: =C2*E2 -> 98.301739 | G2: =F2-D2 -> 41.011746 | H2: =ROUND(100*F2/D2,2)-100 -> 71.59 | J2: =SUM(D:D) -> 2080.7518 | K2: =SUM(F:F) -> 2711.506 | L2: =SUM(G:G) -> 630.75424 | M2: =ROUND(100*K2/J2,2)-100 -> 30.31
A3: AAPL | B3: 183.93 | C3: 0.3381214 | D3: =B3*C3 -> 62.190669 | E3: =IFERROR(__xludf.DUMMYFUNCTION("GOOGLEFINANCE(A3)"),312.51) -> 312.51 | F3: =C3*E3 -> 105.66632 | G3: =F3-D3 -> 43.47565 | H3: =ROUND(100*F3/D3,2)-100 -> 69.91
A4: AMZN | B4: 231.75 | C4: 0.2154063 | D4: =B4*C4 -> 49.92041 | E4: =IFERROR(__xludf.DUMMYFUNCTION("GOOGLEFINANCE(A4)"),274.0) -> 274 | F4: =C4*E4 -> 59.021326 | G4: =F4-D4 -> 9.1009162 | H4: =ROUND(100*F4/D4,2)-100 -> 18.23
A5: AMZN | B5: 232.56 | C5: 0.4293011 | D5: =B5*C5 -> 99.838264 | E5: =IFERROR(__xludf.DUMMYFUNCTION("GOOGLEFINANCE(A5)"),274.0) -> 274 | F5: =C5*E5 -> 117.6285 | G5: =F5-D5 -> 17.790238 | H5: =ROUND(100*F5/D5,2)-100 -> 17.82 | J5: Name | K5: Cost | L5: Current Value | M5: Sector | N5: Percent
A6: GOOGL | B6: 176.49 | C6: 0.0483318 | D6: =B6*C6 -> 8.5300794 | E6: =IFERROR(__xludf.DUMMYFUNCTION("GOOGLEFINANCE(A6)"),390.13) -> 390.13 | F6: =C6*E6 -> 18.855685 | G6: =F6-D6 -> 10.325606 | H6: =ROUND(100*F6/D6,2)-100 -> 121.05 | J6: GOOGL | K6: =SUMIF(A:A,J6,D:D) -> 231.98716 | L6: =SUMIF(A:A,J6,F:F) -> 345.17407 | M6: Technology | N6: =ROUND((100*L6/K6),2)-100 -> 48.79
A7: GOOGL | B7: 240.08 | C7: 0.4158544 | D7: =B7*C7 -> 99.838324 | E7: =IFERROR(__xludf.DUMMYFUNCTION("GOOGLEFINANCE(A7)"),390.13) -> 390.13 | F7: =C7*E7 -> 162.23728 | G7: =F7-D7 -> 62.398953 | H7: =ROUND(100*F7/D7,2)-100 -> 62.5 | J7: AMZN | K7: =SUMIF(A:A,J7,D:D) -> 189.26746 | L7: =SUMIF(A:A,J7,F:F) -> 218.02344 | M7: Consumer | N7: =ROUND((100*L7/K7),2)-100 -> 15.19
A8: GOOGL | B8: 246.85 | C8: 0.18675 | D8: =B8*C8 -> 46.099238 | E8: =IFERROR(__xludf.DUMMYFUNCTION("GOOGLEFINANCE(A8)"),390.13) -> 390.13 | F8: =C8*E8 -> 72.856778 | G8: =F8-D8 -> 26.75754 | H8: =ROUND(100*F8/D8,2)-100 -> 58.04 | J8: AAPL | K8: =SUMIF(A:A,J8,D:D) -> 149.4302 | L8: =SUMIF(A:A,J8,F:F) -> 238.87214 | M8: Technology | N8: =ROUND((100*L8/K8),2)-100 -> 59.86
A9: GOOGL | B9: 331.52 | C9: 0.2338306 | D9: =B9*C9 -> 77.519521 | E9: =IFERROR(__xludf.DUMMYFUNCTION("GOOGLEFINANCE(A9)"),390.13) -> 390.13 | F9: =C9*E9 -> 91.224332 | G9: =F9-D9 -> 13.704811 | H9: =ROUND(100*F9/D9,2)-100 -> 17.68 | J9: JNJ | K9: =SUMIF(A:A,J9,D:D) -> 49.999679 | L9: =SUMIF(A:A,J9,F:F) -> 65.713376 | M9: Health Care | N9: =ROUND((100*L9/K9),2)-100 -> 31.43
A10: JNJ | B10: 175.61 | C10: 0.28472 | D10: =B10*C10 -> 49.999679 | E10: =IFERROR(__xludf.DUMMYFUNCTION("GOOGLEFINANCE(A10)"),230.8) -> 230.8 | F10: =C10*E10 -> 65.713376 | G10: =F10-D10 -> 15.713697 | H10: =ROUND(100*F10/D10,2)-100 -> 31.43 | J10: JPM | K10: =SUMIF(A:A,J10,D:D) -> 53.54295 | L10: =SUMIF(A:A,J10,F:F) -> 52.886188 | M10: Financials | N10: =ROUND((100*L10/K10),2)-100 -> -1.23
A11: JPM | B11: 296.61 | C11: 0.13323 | D11: =B11*C11 -> 39.51735 | E11: =IFERROR(__xludf.DUMMYFUNCTION("GOOGLEFINANCE(A11)"),296.73) -> 296.73 | F11: =C11*E11 -> 39.533338 | G11: =F11-D11 -> 0.0159876 | H11: =ROUND(100*F11/D11,2)-100 -> 0.04 | J11: MSFT | K11: =SUMIF(A:A,J11,D:D) -> 191.07917 | L11: =SUMIF(A:A,J11,F:F) -> 166.89002 | M11: Technology | N11: =ROUND((100*L11/K11),2)-100 -> -12.66
A12: JPM | B12: 311.68 | C12: 0.045 | D12: =B12*C12 -> 14.0256 | E12: =IFERROR(__xludf.DUMMYFUNCTION("GOOGLEFINANCE(A12)"),296.73) -> 296.73 | F12: =C12*E12 -> 13.35285 | G12: =F12-D12 -> -0.67275 | H12: =ROUND(100*F12/D12,2)-100 -> -4.8 | J12: SNDK | K12: =SUMIF(A:A,J12,D:D) -> 99.839945 | L12: =SUMIF(A:A,J12,F:F) -> 274.16488 | M12: Technology | N12: =ROUND((100*L12/K12),2)-100 -> 174.6
A13: MSFT | B13: 426.69 | C13: 0.0818857 | D13: =B13*C13 -> 34.939809 | E13: =IFERROR(__xludf.DUMMYFUNCTION("GOOGLEFINANCE(A13)"),426.99) -> 426.99 | F13: =C13*E13 -> 34.964375 | G13: =F13-D13 -> 0.02456571 | H13: =ROUND(100*F13/D13,2)-100 -> 0.07 | J13: STX | K13: =SUMIF(A:A,J13,D:D) -> 90.588264 | L13: =SUMIF(A:A,J13,F:F) -> 185.71822 | M13: Technology | N13: =ROUND((100*L13/K13),2)-100 -> 105.01
A14: MSFT | B14: 505.36 | C14: 0.3089666 | D14: =B14*C14 -> 156.13936 | E14: =IFERROR(__xludf.DUMMYFUNCTION("GOOGLEFINANCE(A14)"),426.99) -> 426.99 | F14: =C14*E14 -> 131.92565 | G14: =F14-D14 -> -24.213712 | H14: =ROUND(100*F14/D14,2)-100 -> -15.51 | J14: TSM | K14: =SUMIF(A:A,J14,D:D) -> 49.999652 | L14: =SUMIF(A:A,J14,F:F) -> 89.560488 | M14: Technology | N14: =ROUND((100*L14/K14),2)-100 -> 79.12
A15: ONDS | B15: 10.3 | C15: 3 | D15: =B15*C15 -> 30.9 | E15: =IFERROR(__xludf.DUMMYFUNCTION("GOOGLEFINANCE(A15)"),13.25) -> 13.25 | F15: =C15*E15 -> 39.75 | G15: =F15-D15 -> 8.85 | H15: =ROUND(100*F15/D15,2)-100 -> 28.64 | J15: GEV | K15: =SUMIF(A:A,J15,D:D) -> 69.889927 | L15: =SUMIF(A:A,J15,F:F) -> 63.571692 | M15: Energy | N15: =ROUND((100*L15/K15),2)-100 -> -9.04
A16: SNDK | B16: 597.82 | C16: 0.1670067 | D16: =B16*C16 -> 99.839945 | E16: =IFERROR(__xludf.DUMMYFUNCTION("GOOGLEFINANCE(A16)"),1641.64) -> 1641.64 | F16: =C16*E16 -> 274.16488 | G16: =F16-D16 -> 174.32493 | H16: =ROUND(100*F16/D16,2)-100 -> 174.6 | J16: WMT | K16: =SUMIF(A:A,J16,D:D) -> 149.75531 | L16: =SUMIF(A:A,J16,F:F) -> 139.23918 | M16: Consumer | N16: =ROUND((100*L16/K16),2)-100 -> -7.02
A17: STX | B17: 417.74 | C17: 0.1194978 | D17: =B17*C17 -> 49.919011 | E17: =IFERROR(__xludf.DUMMYFUNCTION("GOOGLEFINANCE(A17)"),880.72) -> 880.72 | F17: =C17*E17 -> 105.2441 | G17: =F17-D17 -> 55.325091 | H17: =ROUND(100*F17/D17,2)-100 -> 110.83 | J17: ONDS | K17: =SUMIF(A:A,J17,D:D) -> 30.9 | L17: =SUMIF(A:A,J17,F:F) -> 39.75 | M17: Defense | N17: =ROUND((100*L17/K17),2)-100 -> 28.64
A18: STX | B18: 445.09 | C18: 0.0913731 | D18: =B18*C18 -> 40.669253 | E18: =IFERROR(__xludf.DUMMYFUNCTION("GOOGLEFINANCE(A18)"),880.72) -> 880.72 | F18: =C18*E18 -> 80.474117 | G18: =F18-D18 -> 39.804864 | H18: =ROUND(100*F18/D18,2)-100 -> 97.87 | J18: UNH | K18: =SUMIF(A:A,J18,D:D) -> 99.837057 | L18: =SUMIF(A:A,J18,F:F) -> 133.49647 | M18: Health Care | N18: =ROUND((100*L18/K18),2)-100 -> 33.71
A19: AAPL | B19: 268.15 | C19: 0.1116895 | D19: =B19*C19 -> 29.949539 | E19: =IFERROR(__xludf.DUMMYFUNCTION("GOOGLEFINANCE(A19)"),312.51) -> 312.51 | F19: =C19*E19 -> 34.904086 | G19: =F19-D19 -> 4.9545462 | H19: =ROUND(100*F19/D19,2)-100 -> 16.54 | J19: XBI | K19: =SUMIF(A:A,J19,D:D) -> 89.752885 | L19: =SUMIF(A:A,J19,F:F) -> 98.336246 | M19: Health Care | N19: =ROUND((100*L19/K19),2)-100 -> 9.56
A20: GEV | B20: 1094.99 | C20: 0.063827 | D20: =B20*C20 -> 69.889927 | E20: =IFERROR(__xludf.DUMMYFUNCTION("GOOGLEFINANCE(A20)"),996.0) -> 996 | F20: =C20*E20 -> 63.571692 | G20: =F20-D20 -> -6.3182347 | H20: =ROUND(100*F20/D20,2)-100 -> -9.04 | J20: RKLB | K20: =SUMIF(A:A,J20,D:D) -> 43.129975 | L20: =SUMIF(A:A,J20,F:F) -> 95.849425 | M20: Space | N20: =ROUND((100*L20/K20),2)-100 -> 122.23
A21: AMZN | B21: 261.65 | C21: 0.1509986 | D21: =B21*C21 -> 39.508784 | E21: =IFERROR(__xludf.DUMMYFUNCTION("GOOGLEFINANCE(A21)"),274.0) -> 274 | F21: =C21*E21 -> 41.373616 | G21: =F21-D21 -> 1.8648327 | H21: =ROUND(100*F21/D21,2)-100 -> 4.72 | J21: LITE | K21: =SUMIF(A:A,J21,D:D) -> 74.879658 | L21: =SUMIF(A:A,J21,F:F) -> 66.210078 | M21: Technology | N21: =ROUND((100*L21/K21),2)-100 -> -11.58
A22: TSM | B22: 237.19 | C22: 0.2108 | D22: =B22*C22 -> 49.999652 | E22: =IFERROR(__xludf.DUMMYFUNCTION("GOOGLEFINANCE(A22)"),424.86) -> 424.86 | F22: =C22*E22 -> 89.560488 | G22: =F22-D22 -> 39.560836 | H22: =ROUND(100*F22/D22,2)-100 -> 79.12 | J22: ASTS | K22: =SUMIF(A:A,J22,D:D) -> 15.448512 | L22: =SUMIF(A:A,J22,F:F) -> 24.700173 | M22: Space | N22: =ROUND((100*L22/K22),2)-100 -> 59.89
A23: WMT | B23: 127.88 | C23: 1.1710612 | D23: =B23*C23 -> 149.75531 | E23: =IFERROR(__xludf.DUMMYFUNCTION("GOOGLEFINANCE(A23)"),118.9) -> 118.9 | F23: =C23*E23 -> 139.23918 | G23: =F23-D23 -> -10.51613 | H23: =ROUND(100*F23/D23,2)-100 -> -7.02 | J23: RBRK | K23: =SUMIF(A:A,J23,D:D) -> 44.926793 | L23: =SUMIF(A:A,J23,F:F) -> 56.294585 | M23: Technology | N23: =ROUND((100*L23/K23),2)-100 -> 25.3
A24: XOM | B24: 153.53 | C24: 0.9753937 | D24: =B24*C24 -> 149.75219 | E24: =IFERROR(__xludf.DUMMYFUNCTION("GOOGLEFINANCE(A24)"),146.96) -> 146.96 | F24: =C24*E24 -> 143.34386 | G24: =F24-D24 -> -6.4083366 | H24: =ROUND(100*F24/D24,2)-100 -> -4.28 | J24: NOK | K24: =SUMIF(A:A,J24,D:D) -> 52.416699 | L24: =SUMIF(A:A,J24,F:F) -> 60.447333 | M24: Technology | N24: =ROUND((100*L24/K24),2)-100 -> 15.32
A25: XBI | B25: 124.12 | C25: 0.7231138 | D25: =B25*C25 -> 89.752885 | E25: =IFERROR(__xludf.DUMMYFUNCTION("GOOGLEFINANCE(A25)"),135.99) -> 135.99 | F25: =C25*E25 -> 98.336246 | G25: =F25-D25 -> 8.5833608 | H25: =ROUND(100*F25/D25,2)-100 -> 9.56 | J25: PRME | K25: =SUMIF(A:A,J25,D:D) -> 30.09 | L25: =SUMIF(A:A,J25,F:F) -> 34.797959 | M25: Health Care | N25: =ROUND((100*L25/K25),2)-100 -> 15.65
A26: UNH | B26: 286.08 | C26: 0.348983 | D26: =B26*C26 -> 99.837057 | E26: =IFERROR(__xludf.DUMMYFUNCTION("GOOGLEFINANCE(A26)"),382.53) -> 382.53 | F26: =C26*E26 -> 133.49647 | G26: =F26-D26 -> 33.65941 | H26: =ROUND(100*F26/D26,2)-100 -> 33.71 | J26: AAOI | K26: =SUMIF(A:A,J26,D:D) -> 84.859079 | L26: =SUMIF(A:A,J26,F:F) -> 77.617195 | M26: Technology | N26: =ROUND((100*L26/K26),2)-100 -> -8.53
A27: RKLB | B27: 66.61 | C27: 0.6475 | D27: =B27*C27 -> 43.129975 | E27: =IFERROR(__xludf.DUMMYFUNCTION("GOOGLEFINANCE(A27)"),148.03) -> 148.03 | F27: =C27*E27 -> 95.849425 | G27: =F27-D27 -> 52.71945 | H27: =ROUND(100*F27/D27,2)-100 -> 122.23 | J27: MRVL | K27: =SUMIF(A:A,J27,D:D) -> 39.379191 | L27: =SUMIF(A:A,J27,F:F) -> 40.848981 | M27: Technology | N27: =ROUND((100*L27/K27),2)-100 -> 3.73
A28: ASTS | B28: 83.24 | C28: 0.18559 | D28: =B28*C28 -> 15.448512 | E28: =IFERROR(__xludf.DUMMYFUNCTION("GOOGLEFINANCE(A28)"),133.09) -> 133.09 | F28: =C28*E28 -> 24.700173 | G28: =F28-D28 -> 9.2516615 | H28: =ROUND(100*F28/D28,2)-100 -> 59.89
A29: AAOI | B29: 184.79 | C29: 0.459219 | D29: =B29*C29 -> 84.859079 | E29: =IFERROR(__xludf.DUMMYFUNCTION("GOOGLEFINANCE(A29)"),169.02) -> 169.02 | F29: =C29*E29 -> 77.617195 | G29: =F29-D29 -> -7.2418836 | H29: =ROUND(100*F29/D29,2)-100 -> -8.53
A30: NOK | B30: 13.25 | C30: 3.9559773 | D30: =B30*C30 -> 52.416699 | E30: =IFERROR(__xludf.DUMMYFUNCTION("GOOGLEFINANCE(A30)"),15.28) -> 15.28 | F30: =C30*E30 -> 60.447333 | G30: =F30-D30 -> 8.0306339 | H30: =ROUND(100*F30/D30,2)-100 -> 15.32
A31: LITE | B31: 973.31 | C31: 0.076933 | D31: =B31*C31 -> 74.879658 | E31: =IFERROR(__xludf.DUMMYFUNCTION("GOOGLEFINANCE(A31)"),860.62) -> 860.62 | F31: =C31*E31 -> 66.210078 | G31: =F31-D31 -> -8.6695798 | H31: =ROUND(100*F31/D31,2)-100 -> -11.58
A32: RBRK | B32: 56.12 | C32: 0.8005487 | D32: =B32*C32 -> 44.926793 | E32: =IFERROR(__xludf.DUMMYFUNCTION("GOOGLEFINANCE(A32)"),70.32) -> 70.32 | F32: =C32*E32 -> 56.294585 | G32: =F32-D32 -> 11.367792 | H32: =ROUND(100*F32/D32,2)-100 -> 25.3
A33: PRME | B33: 2.94 | C33: 10.234694 | D33: =B33*C33 -> 30.09 | E33: =IFERROR(__xludf.DUMMYFUNCTION("GOOGLEFINANCE(A33)"),3.4) -> 3.4 | F33: =C33*E33 -> 34.797959 | G33: =F33-D33 -> 4.7079591 | H33: =ROUND(100*F33/D33,2)-100 -> 15.65
A34: MRVL | B34: 197.46 | C34: 0.1994287 | D34: =B34*C34 -> 39.379191 | E34: =IFERROR(__xludf.DUMMYFUNCTION("GOOGLEFINANCE(A34)"),204.83) -> 204.83 | F34: =C34*E34 -> 40.848981 | G34: =F34-D34 -> 1.4697895 | H34: =ROUND(100*F34/D34,2)-100 -> 3.73
J36: Sector | K36: Cost | L36: Profit | M36: Percent
J37: Technology | K37: =SUMIF(USA_STOCK_SUMMARIZE[Sector],J37,USA_STOCK_SUMMARIZE[Cost]) -> 1109.3858 | L37: =SUMIF(USA_STOCK_SUMMARIZE[Sector],J37,USA_STOCK_SUMMARIZE[Current Value]) -> 1601.798 | M37: =ROUND((100*L37/K37),2)-100 -> 44.39
J38: Consumer | K38: =SUMIF(USA_STOCK_SUMMARIZE[Sector],J38,USA_STOCK_SUMMARIZE[Cost]) -> 339.02276 | L38: =SUMIF(USA_STOCK_SUMMARIZE[Sector],J38,USA_STOCK_SUMMARIZE[Current Value]) -> 357.26262 | M38: =ROUND((100*L38/K38),2)-100 -> 5.38
J39: Health Care | K39: =SUMIF(USA_STOCK_SUMMARIZE[Sector],J39,USA_STOCK_SUMMARIZE[Cost]) -> 269.67962 | L39: =SUMIF(USA_STOCK_SUMMARIZE[Sector],J39,USA_STOCK_SUMMARIZE[Current Value]) -> 332.34405 | M39: =ROUND((100*L39/K39),2)-100 -> 23.24
J40: Financials | K40: =SUMIF(USA_STOCK_SUMMARIZE[Sector],J40,USA_STOCK_SUMMARIZE[Cost]) -> 53.54295 | L40: =SUMIF(USA_STOCK_SUMMARIZE[Sector],J40,USA_STOCK_SUMMARIZE[Current Value]) -> 52.886188 | M40: =ROUND((100*L40/K40),2)-100 -> -1.23
J41: Defense | K41: =SUMIF(USA_STOCK_SUMMARIZE[Sector],J41,USA_STOCK_SUMMARIZE[Cost]) -> 30.9 | L41: =SUMIF(USA_STOCK_SUMMARIZE[Sector],J41,USA_STOCK_SUMMARIZE[Current Value]) -> 39.75 | M41: =ROUND((100*L41/K41),2)-100 -> 28.64
...

Sheet ETF
A1: Name | B1: Purchase price | C1: Quantity | D1: Cost | E1: Current Price | F1: Current Value | G1: Profit | H1: Percent | J1: Net Cost | K1: Net Current Value | L1: Net Profit | M1: Net Percent
A2: QQQM | B2: 234.18 | C2: 0.651732 | D2: =B2*C2 -> 152.6226 | E2: =IFERROR(__xludf.DUMMYFUNCTION("GOOGLEFINANCE(A2)"),302.85) -> 302.85 | F2: =C2*E2 -> 197.37704 | G2: =F2-D2 -> 44.754436 | H2: =ROUND(100*F2/D2,2)-100 -> 29.32 | J2: =SUM(D:D) -> 563.70544 | K2: =SUM(F:F) -> 693.84473 | L2: =SUM(G:G) -> 130.13929 | M2: =ROUND(100*K2/J2,2)-100 -> 23.09
A3: SMH | B3: 385.54 | C3: 0.12839 | D3: =B3*C3 -> 49.499481 | E3: =IFERROR(__xludf.DUMMYFUNCTION("GOOGLEFINANCE(A3)"),599.83) -> 599.83 | F3: =C3*E3 -> 77.012174 | G3: =F3-D3 -> 27.512693 | H3: =ROUND(100*F3/D3,2)-100 -> 55.58
A4: VOO | B4: 609.72 | C4: 0.022 | D4: =B4*C4 -> 13.41384 | E4: =IFERROR(__xludf.DUMMYFUNCTION("GOOGLEFINANCE(A4)"),693.91) -> 693.91 | F4: =C4*E4 -> 15.26602 | G4: =F4-D4 -> 1.85218 | H4: =ROUND(100*F4/D4,2)-100 -> 13.81
A5: VOO | B5: 613.41 | C5: 0.01829 | D5: =B5*C5 -> 11.219269 | E5: =IFERROR(__xludf.DUMMYFUNCTION("GOOGLEFINANCE(A5)"),693.91) -> 693.91 | F5: =C5*E5 -> 12.691614 | G5: =F5-D5 -> 1.472345 | H5: =ROUND(100*F5/D5,2)-100 -> 13.12 | J5: Name | K5: Cost | L5: Current Value | M5: Sector | N5: Percent
A6: VOO | B6: 622.08 | C6: 0.08841 | D6: =B6*C6 -> 54.998093 | E6: =IFERROR(__xludf.DUMMYFUNCTION("GOOGLEFINANCE(A6)"),693.91) -> 693.91 | F6: =C6*E6 -> 61.348583 | G6: =F6-D6 -> 6.3504903 | H6: =ROUND(100*F6/D6,2)-100 -> 11.55 | J6: QQQM | K6: =SUMIF(A:A,J6,D:D) -> 203.36099 | L6: =SUMIF(A:A,J6,F:F) -> 258.27396 | M6: Technology | N6: =ROUND((100*L6/K6),2)-100 -> 27
A7: VOO | B7: 627.61 | C7: 0.07648 | D7: =B7*C7 -> 47.999613 | E7: =IFERROR(__xludf.DUMMYFUNCTION("GOOGLEFINANCE(A7)"),693.91) -> 693.91 | F7: =C7*E7 -> 53.070237 | G7: =F7-D7 -> 5.070624 | H7: =ROUND(100*F7/D7,2)-100 -> 10.56 | J7: VOO | K7: =SUMIF(A:A,J7,D:D) -> 270.62297 | L7: =SUMIF(A:A,J7,F:F) -> 298.57559 | M7: S&P | N7: =ROUND((100*L7/K7),2)-100 -> 10.33
A8: QQQM | B8: 252.33 | C8: 0.2010795 | D8: =B8*C8 -> 50.73839 | E8: =IFERROR(__xludf.DUMMYFUNCTION("GOOGLEFINANCE(A8)"),302.85) -> 302.85 | F8: =C8*E8 -> 60.896927 | G8: =F8-D8 -> 10.158536 | H8: =ROUND(100*F8/D8,2)-100 -> 20.02 | J8: SMH | K8: =SUMIF(A:A,J8,D:D) -> 89.721481 | L8: =SUMIF(A:A,J8,F:F) -> 136.99517 | M8: Technology | N8: =ROUND((100*L8/K8),2)-100 -> 52.69
A9: SMH | B9: 402.22 | C9: 0.1 | D9: =B9*C9 -> 40.222 | E9: =IFERROR(__xludf.DUMMYFUNCTION("GOOGLEFINANCE(A9)"),599.83) -> 599.83 | F9: =C9*E9 -> 59.983 | G9: =F9-D9 -> 19.761 | H9: =ROUND(100*F9/D9,2)-100 -> 49.13
A10: VOO | B10: 633.32 | C10: 0.15 | D10: =B10*C10 -> 94.998 | E10: =IFERROR(__xludf.DUMMYFUNCTION("GOOGLEFINANCE(A10)"),693.91) -> 693.91 | F10: =C10*E10 -> 104.0865 | G10: =F10-D10 -> 9.0885 | H10: =ROUND(100*F10/D10,2)-100 -> 9.57
A11: VOO | B11: 639.07 | C11: 0.0751 | D11: =B11*C11 -> 47.994157 | E11: =IFERROR(__xludf.DUMMYFUNCTION("GOOGLEFINANCE(A11)"),693.91) -> 693.91 | F11: =C11*E11 -> 52.112641 | G11: =F11-D11 -> 4.118484 | H11: =ROUND(100*F11/D11,2)-100 -> 8.58
J12: Sector | K12: Cost | L12: Profit | M12: Percent
J13: Technology | K13: =SUMIF(ETF_SUMMARIZE[Sector],J13,ETF_SUMMARIZE[Cost]) -> 293.08247 | L13: =SUMIF(ETF_SUMMARIZE[Sector],J13,ETF_SUMMARIZE[Current Value]) -> 395.26914 | M13: =ROUND((100*L13/K13),2)-100 -> 34.87
J14: S&P | K14: =SUMIF(ETF_SUMMARIZE[Sector],J14,ETF_SUMMARIZE[Cost]) -> 270.62297 | L14: =SUMIF(ETF_SUMMARIZE[Sector],J14,ETF_SUMMARIZE[Current Value]) -> 298.57559 | M14: =ROUND((100*L14/K14),2)-100 -> 10.33

Sheet Crypto
A1: Name | B1: Currency | C1: Purchase price | D1: Quantity | E1: Cost | F1: Current Price | G1: Current Value | H1: Profit | I1: Percent | K1: Net Cost | L1: Net Current Value | M1: Net Profit | N1: Net Percent
A2: SOL | B2: THB | C2: 2836.48 | D2: =0.00175922+0.70157378 -> 0.703333 | E2: =C2*D2 -> 1994.99 | F2: =IFERROR(__xludf.DUMMYFUNCTION("VALUE(REGEXEXTRACT( IMPORTDATA(""https://api.coingecko.com/api/v3/simple/price?ids=solana&vs_currencies=thb""), ""[0-9.]+"" ))*M14"),"Loading...") -> Loading... | G2: =D2*F2 -> Loading... | H2: =G2-E2 -> Loading... | I2: =ROUND((100*G2)/E2,2)-100 -> Loading... | K2: =SUM(E:E) -> 7979.9729 | L2: =SUM(G:G) -> Loading... | M2: =SUM(H:H) -> Loading... | N2: =ROUND(100*L2/K2,2)-100 -> Loading...
A3: BTCTHB | B3: THB | C3: 2289650 | D3: 0.00043565 | E3: =C3*D3 -> 997.48602 | F3: =IFERROR(__xludf.DUMMYFUNCTION("GOOGLEFINANCE(A3)"),2390689.316) -> 2390689.3 | G3: =D3*F3 -> 1041.5038 | H3: =G3-E3 -> 44.017778 | I3: =ROUND((100*G3)/E3,2)-100 -> 4.41
A4: BTCTHB | B4: THB | C4: 2787022.5 | D4: 0.00071581 | E4: =C4*D4 -> 1994.9786 | F4: =IFERROR(__xludf.DUMMYFUNCTION("GOOGLEFINANCE(A4)"),2390689.316) -> 2390689.3 | G4: =D4*F4 -> 1711.2793 | H4: =G4-E4 -> -283.69928 | I4: =ROUND((100*G4)/E4,2)-100 -> -14.22
A5: BTCTHB | B5: THB | C5: 3681286 | D5: 0.00027164 | E5: =C5*D5 -> 999.98454 | F5: =IFERROR(__xludf.DUMMYFUNCTION("GOOGLEFINANCE(A5)"),2390689.316) -> 2390689.3 | G5: =D5*F5 -> 649.40685 | H5: =G5-E5 -> -350.57769 | I5: =ROUND((100*G5)/E5,2)-100 -> -35.06 | K5: Name | L5: Cost | M5: Current Value | N5: Percent
A6: BTCTHB | B6: THB | C6: 3701800.9 | D6: 0.00021464 | E6: =C6*D6 -> 794.55455 | F6: =IFERROR(__xludf.DUMMYFUNCTION("GOOGLEFINANCE(A6)"),2390689.316) -> 2390689.3 | G6: =D6*F6 -> 513.13755 | H6: =G6-E6 -> -281.41699 | I6: =ROUND((100*G6)/E6,2)-100 -> -35.42 | K6: BTCTHB | L6: =SUMIF(A:A,K6,E:E) -> 4787.0037 | M6: =SUMIF(A:A,K6,G:G) -> 3915.3275 | N6: =ROUND((100*M6/L6),2)-100 -> -18.21
A7: ETHTHB | B7: THB | C7: 142510.71 | D7: 0.00840624 | E7: =C7*D7 -> 1197.9792 | F7: =IFERROR(__xludf.DUMMYFUNCTION("GOOGLEFINANCE(A7)"),65304.863020000004) -> 65304.863 | G7: =D7*F7 -> 548.96835 | H7: =G7-E7 -> -649.01088 | I7: =ROUND((100*G7)/E7,2)-100 -> -54.18 | K7: ETHTHB | L7: =SUMIF(A:A,K7,E:E) -> 1197.9792 | M7: =SUMIF(A:A,K7,G:G) -> 548.96835 | N7: =ROUND((100*M7/L7),2)-100 -> -54.18
K8: SOL | L8: =SUMIF(A:A,K8,E:E) -> 1994.99 | M8: =SUMIF(A:A,K8,G:G) -> Loading... | N8: =ROUND((100*M8/L8),2)-100 -> Loading...
K13: From | L13: To | M13: Chang Rate
K14: USD | L14: THB | M14: =IFERROR(__xludf.DUMMYFUNCTION("GOOGLEFINANCE(""CURRENCY:""&K14&L14) "),32.564) -> 32.564
K15: THB | L15: USD | M15: =IFERROR(__xludf.DUMMYFUNCTION("GOOGLEFINANCE(""CURRENCY:""&K15&L15) "),0.03070782) -> 0.03070782

Sheet Other
A1: Type | B1: Name | C1: Purchase price | D1: Quantity | E1: Cost | F1: Current Price | G1: Current Value | H1: Profit | I1: Percent | K1: Net Cost | L1: Net Current Value | M1: Net Profit | N1: Net Percent
A2: Provident Fund | B2: Provident Fund | C2: 68426.28 | D2: 1 | E2: =C2*D2 -> 68426.28 | F2: 69527.77 | G2: =D2*F2 -> 69527.77 | H2: =G2-E2 -> 1101.49 | I2: =ROUND((100*G2)/E2,2)-100 -> 1.61 | K2: =SUM(E:E) -> 578426.31 | L2: =SUM(G:G) -> 579527.8 | M2: =SUM(H:H) -> 1101.49 | N2: =ROUND(100*L2/K2,2)-100 -> 0.19
A3: Insurance | B3: ประกันสะสมทรัพย์ | C3: 300000.03 | D3: 1 | E3: =C3*D3 -> 300000.03 | F3: =C3 -> 300000.03 | G3: =D3*F3 -> 300000.03 | H3: =G3-E3 -> 0 | I3: =ROUND((100*G3)/E3,2)-100 -> 0
A4: Debenture | B4: BCP292A | C4: 40000 | D4: 1 | E4: =C4*D4 -> 40000 | F4: =C4 -> 40000 | G4: =D4*F4 -> 40000 | H4: =G4-E4 -> 0 | I4: =ROUND((100*G4)/E4,2)-100 -> 0
A5: Debenture | B5: BCP26NB | C5: 10000 | D5: 1 | E5: =C5*D5 -> 10000 | F5: =C5 -> 10000 | G5: =D5*F5 -> 10000 | H5: =G5-E5 -> 0 | I5: =ROUND((100*G5)/E5,2)-100 -> 0
A6: Debenture | B6: CPALL245B | C6: 5000 | D6: 1 | E6: =C6*D6 -> 5000 | F6: =C6 -> 5000 | G6: =D6*F6 -> 5000 | H6: =G6-E6 -> 0 | I6: =ROUND((100*G6)/E6,2)-100 -> 0
A7: Debenture | B7: GULF298A | C7: 5000 | D7: 1 | E7: =C7*D7 -> 5000 | F7: =C7 -> 5000 | G7: =D7*F7 -> 5000 | H7: =G7-E7 -> 0 | I7: =ROUND((100*G7)/E7,2)-100 -> 0 | K7: Name | L7: Cost | M7: Current Value | N7: Net Profit | O7: Net Percent
A8: Debenture | B8: MTC286A | C8: 100000 | D8: 1 | E8: =C8*D8 -> 100000 | F8: =C8 -> 100000 | G8: =D8*F8 -> 100000 | H8: =G8-E8 -> 0 | I8: =ROUND((100*G8)/E8,2)-100 -> 0 | K8: Insurance | L8: =SUMIF(A:A,K8,E:E) -> 300000.03 | M8: =SUMIF(A:A,K8,G:G) -> 300000.03 | N8: =M8-L8 -> 0 | O8: =ROUND((100*M8)/L8,2)-100 -> 0
A9: Bond | B9: SB348B | C9: 50000 | D9: 1 | E9: =C9*D9 -> 50000 | F9: =C9 -> 50000 | G9: =D9*F9 -> 50000 | H9: =G9-E9 -> 0 | I9: =ROUND((100*G9)/E9,2)-100 -> 0 | K9: Debenture | L9: =SUMIF(A:A,K9,E:E) -> 160000 | M9: =SUMIF(A:A,K9,G:G) -> 160000 | N9: =M9-L9 -> 0 | O9: =ROUND((100*M9)/L9,2)-100 -> 0
K10: Bond | L10: =SUMIF(A:A,K10,E:E) -> 50000 | M10: =SUMIF(A:A,K10,G:G) -> 50000 | N10: =M10-L10 -> 0 | O10: =ROUND((100*M10)/L10,2)-100 -> 0
K11: Provident Fund | L11: =SUMIF(A:A,K11,E:E) -> 68426.28 | M11: =SUMIF(A:A,K11,G:G) -> 69527.77 | N11: =M11-L11 -> 1101.49 | O11: =ROUND((100*M11)/L11,2)-100 -> 1.61

Sheet Gold
A1: Name | B1: Purchase price | C1: Quantity | D1: Cost | E1: Current Price | F1: Current Value | G1: Profit | H1: Percent | J1: Net Cost | K1: Net Current Value | L1: Net Profit | M1: Net Percent | Q1: Name | R1: Purchase price | S1: Quantity | T1: Cost | U1: Current Price | V1: Current Value | W1: Profit | X1: Percent | Z1: weight (OZ) | AA1: gram | AB1: weight (THB)
A2: GOLD | B2: 1992.78 | C2: 0.0138 | D2: =B2*C2 -> 27.500364 | E2: =YAHOO_PRICE("GC=F") -> 4535.3 | F2: =C2*E2 -> 62.58714 | G2: =F2-D2 -> 35.086776 | H2: =ROUND((100*F2)/D2,2)-100 -> 127.59 | J2: =SUM(D:D) + (SUM(T:T)*AB8) -> 448.53265 | K2: =SUM(F:F) + (SUM(V:V)*AB8) -> 599.66537 | L2: =SUM(G:G) -> 152.4433 | M2: =ROUND(100*K2/J2,2)-100 -> 33.69 | Q2: GOLD | R2: 71960 | S2: 0.2118 | T2: =R2*S2/AA2 -> 999.8116 | U2: =YAHOO_PRICE("GC=F")/AB3*AB7 -> 72183.533 | V2: =S2*U2/AA2 -> 1002.9174 | W2: =V2-T2 -> 3.1057701 | X2: =ROUND((100*V2)/T2,2)-100 -> 0.31 | Z2: 0.49 | AA2: 15.244 | AB2: 1
A3: GOLD | B3: 2877.45 | C3: 0.0509 | D3: =B3*C3 -> 146.46221 | E3: =YAHOO_PRICE("GC=F") -> 4535.3 | F3: =C3*E3 -> 230.84677 | G3: =F3-D3 -> 84.384565 | H3: =ROUND((100*F3)/D3,2)-100 -> 57.62 | Q3: GOLD | R3: 77060 | S3: 0.1978 | T3: =R3*S3/AA2 -> 999.8995 | U3: 73531.49 | V3: =S3*U3/AA2 -> 954.11498 | W3: =V3-T3 -> -45.784524 | X3: =ROUND((100*V3)/T3,2)-100 -> -4.58 | Z3: 1 | AA3: 31.104 | AB3: 2.046
A4: GOLD | B4: 3312.04 | C4: 0.0008 | D4: =B4*C4 -> 2.649632 | E4: =YAHOO_PRICE("GC=F") -> 4535.3 | F4: =C4*E4 -> 3.62824 | G4: =F4-D4 -> 0.978608 | H4: =ROUND((100*F4)/D4,2)-100 -> 36.93
A5: GOLD | B5: 3230.55 | C5: 0.0046 | D5: =B5*C5 -> 14.86053 | E5: =YAHOO_PRICE("GC=F") -> 4535.3 | F5: =C5*E5 -> 20.86238 | G5: =F5-D5 -> 6.00185 | H5: =ROUND((100*F5)/D5,2)-100 -> 40.39 | J5: Name | K5: Cost | L5: Current Value
A6: GOLD | B6: 3289.35 | C6: 0.0184 | D6: =B6*C6 -> 60.52404 | E6: =YAHOO_PRICE("GC=F") -> 4535.3 | F6: =C6*E6 -> 83.44952 | G6: =F6-D6 -> 22.92548 | H6: =ROUND((100*F6)/D6,2)-100 -> 37.88 | J6: GOLD | K6: =SUMIF(A:A,J6,D:D) + (SUMIF(Q:Q,J6,T:T)*AB8) -> 448.53265 | L6: =SUMIF(A:A,J6,F:F)+ (SUMIF(Q:Q,J6,V:V)*AB8) -> 599.66537 | Z6: From | AA6: To | AB6: Chang Rate
A7: GOLD | B7: 3857.46 | C7: 0.0159 | D7: =B7*C7 -> 61.333614 | E7: =YAHOO_PRICE("GC=F") -> 4535.3 | F7: =C7*E7 -> 72.11127 | G7: =F7-D7 -> 10.777656 | H7: =ROUND((100*F7)/D7,2)-100 -> 17.57 | Z7: USD | AA7: THB | AB7: =IFERROR(__xludf.DUMMYFUNCTION("GOOGLEFINANCE(""CURRENCY:""&Z7&AA7) "),32.564) -> 32.564
A8: GOLD | B8: 4791.96 | C8: 0.000212 | D8: =B8*C8 -> 1.0158955 | E8: =YAHOO_PRICE("GC=F") -> 4535.3 | F8: =C8*E8 -> 0.9614836 | G8: =F8-D8 -> -0.05441192 | H8: =ROUND((100*F8)/D8,2)-100 -> -5.36 | Z8: THB | AA8: USD | AB8: =IFERROR(__xludf.DUMMYFUNCTION("GOOGLEFINANCE(""CURRENCY:""&Z8&AA8) "),0.03070782) -> 0.03070782
A9: GOLD | B9: 5068.57 | C9: 0.014359 | D9: =B9*C9 -> 72.779597 | E9: =YAHOO_PRICE("GC=F") -> 4535.3 | F9: =C9*E9 -> 65.122373 | G9: =F9-D9 -> -7.6572239 | H9: =ROUND((100*F9)/D9,2)-100 -> -10.52

Sheet Profit
A1: Date | B1: Name | C1: Type | D1: Cost | E1: Sell Price | F1: Profit | G1: Percent | I1: Date | J1: Name | K1: Type | L1: Cost | M1: Sell Price | N1: Profit | O1: Percent | Q1: Net Cost | R1: Net Current Value | S1: Net Profit | T1: Net Percent
A2: 19/03/2026 | B2: TISCOCH | C2: Fund | D2: 5000 | E2: 4778.59 | F2: =E2-D2 -> -221.41 | G2: =ROUND(100*F2/D2,2) -> -4.43 | I2: 17/03/2026 | J2: LLY | K2: USA Stock | L2: =62.24+100.69 -> 162.93 | M2: 187.54 | N2: =M2-L2 -> 24.61 | O2: =ROUND(100*N2/L2,2) -> 15.1 | Q2: =SUM(D:D) -> 20000 | R2: =SUM(E:E) -> 20237.04 | S2: =SUM(F:F) -> 237.04 | T2: =ROUND(100*R2/Q2,2)-100 -> 1.19
A3: 19/03/2026 | B3: SCBNK225 | C3: Fund | D3: 1500 | E3: 1530.71 | F3: =E3-D3 -> 30.71 | G3: =ROUND(100*F3/D3,2) -> 2.05 | I3: 17/03/2026 | J3: XLE | K3: USA Stock | L3: 36.759738 | M3: =0.66973*59.8134 -> 40.058828 | N3: =M3-L3 -> 3.29909 | O3: =ROUND(100*N3/L3,2) -> 8.97
A4: 19/03/2026 | B4: SCBS&P500 | C4: Fund | D4: 5500 | E4: 5398.59 | F4: =E4-D4 -> -101.41 | G4: =ROUND(100*F4/D4,2) -> -1.84 | I4: 17/03/2026 | J4: XOM | K4: USA Stock | L4: 149.75219 | M4: 158.78 | N4: =M4-L4 -> 9.0278052 | O4: =ROUND(100*N4/L4,2) -> 6.03
A5: 31/03/2027 | B5: SCBCOMP | C5: Fund | D5: 8000 | E5: 8529.15 | F5: =E5-D5 -> 529.15 | G5: =ROUND(100*F5/D5,2) -> 6.61 | I5: 27/04/2026 | J5: TSLA | K5: USA Stock | L5: 116.3 | M5: 120.97 | N5: =M5-L5 -> 4.67 | O5: =ROUND(100*N5/L5,2) -> 4.02 | Q5: Net Cost | R5: Net Current Value | S5: Net Profit | T5: Net Percent
I6: 27/04/2026 | J6: XIB | K6: USA Stock | L6: 89.75 | M6: 96.79 | N6: =M6-L6 -> 7.04 | O6: =ROUND(100*N6/L6,2) -> 7.84 | Q6: =SUM(L:L) -> 943.32193 | R6: =SUM(M:M) -> 983.93883 | S6: =SUM(N:N) -> 40.616895 | T6: =ROUND(100*R6/Q6,2)-100 -> 4.31
I7: 46117 | J7: QYLD | K7: USA Stock | L7: =19.47+60 -> 79.47 | M7: 81.41 | N7: =M7-L7 -> 1.94 | O7: =ROUND(100*N7/L7,2) -> 2.44
I8: 46117 | J8: VXUS | K8: USA Stock | L8: 65.09 | M8: 64.62 | N8: =M8-L8 -> -0.47 | O8: =ROUND(100*N8/L8,2) -> -0.72
I9: 46117 | J9: XYLD | K9: USA Stock | L9: =12.46+81.43 -> 93.89 | M9: 93.12 | N9: =M9-L9 -> -0.77 | O9: =ROUND(100*N9/L9,2) -> -0.82
I10: 46153 | J10: V | K10: USA Stock | L10: =62+15.93 -> 77.93 | M10: 71.44 | N10: =M10-L10 -> -6.49 | O10: =ROUND(100*N10/L10,2) -> -8.33
I11: 46161 | J11: INTC | K11: USA Stock | L11: 36.44 | M11: 30.02 | N11: =M11-L11 -> -6.42 | O11: =ROUND(100*N11/L11,2) -> -17.62
I12: 26/05/2026 | J12: PG | K12: USA Stock | L12: 0.01 | M12: 1.51 | N12: =M12-L12 -> 1.5 | O12: =ROUND(100*N12/L12,2) -> 15000
I13: 46117 | J13: POET | K13: USA Stock | L13: 35 | M13: 37.68 | N13: =M13-L13 -> 2.68 | O13: =ROUND(100*N13/L13,2) -> 7.66
Q15: From | R15: To | S15: Chang Rate
Q16: USD | R16: THB | S16: =IFERROR(__xludf.DUMMYFUNCTION("GOOGLEFINANCE(""CURRENCY:""&Q16&R16) "),32.564) -> 32.564
Q17: THB | R17: USD | S17: =IFERROR(__xludf.DUMMYFUNCTION("GOOGLEFINANCE(""CURRENCY:""&Q17&R17) "),0.03070782) -> 0.03070782

Sheet Summarize
B1: Net Cost | C1: Net Current Value | D1: Net Profit | E1: Net Percent | F1: Currency | H1: From | I1: To | J1: Chang Rate
A2: Thai Stock | B2: ='Thai Stock'!J2 -> 28800 | C2: ='Thai Stock'!K2 -> 35525 | D2: ='Thai Stock'!L2 -> 6725 | E2: ='Thai Stock'!M2 -> 23.35 | F2: THB | H2: USD | I2: THB | J2: =IFERROR(__xludf.DUMMYFUNCTION("GOOGLEFINANCE(""CURRENCY:""&H2&I2) "),32.564) -> 32.564
A3: USA Stock | B3: ='USA Stock'!J2 -> 2080.7518 | C3: ='USA Stock'!K2 -> 2711.506 | D3: ='USA Stock'!L2 -> 630.75424 | E3: ='USA Stock'!M2 -> 30.31 | F3: USD | H3: THB | I3: USD | J3: =IFERROR(__xludf.DUMMYFUNCTION("GOOGLEFINANCE(""CURRENCY:""&H3&I3) "),0.03070782) -> 0.03070782
A4: ETF | B4: =ETF!J2 -> 563.70544 | C4: =ETF!K2 -> 693.84473 | D4: =ETF!L2 -> 130.13929 | E4: =ETF!M2 -> 23.09 | F4: USD
A5: Fund | B5: =Fund!J2 -> 37162.443 | C5: =Fund!K2 -> 45957.767 | D5: =Fund!L2 -> 8795.3246 | E5: =Fund!M2 -> 23.67 | F5: THB
A6: Crypto | B6: =Crypto!K2 -> 7979.9729 | C6: =Crypto!L2 -> Loading... | D6: =Crypto!M2 -> Loading... | E6: =Crypto!N2 -> Loading... | F6: THB
A7: Gold | B7: =Gold!J2 -> 448.53265 | C7: =Gold!K2 -> 599.66537 | D7: =Gold!L2 -> 152.4433 | E7: =Gold!M2 -> 33.69 | F7: USD
A8: Insurance | B8: =Other!L8 -> 300000.03 | C8: =Other!M8 -> 300000.03 | D8: =Other!N8 -> 0 | E8: =Other!O8 -> 0 | F8: THB
A9: Debenture | B9: =Other!L9 -> 160000 | C9: =Other!M9 -> 160000 | D9: =Other!N9 -> 0 | E9: =Other!O9 -> 0 | F9: THB
A10: Bond | B10: =Other!L10 -> 50000 | C10: =Other!M10 -> 50000 | D10: =Other!N10 -> 0 | E10: =Other!O10 -> 0 | F10: THB
A11: Provident Fund | B11: =Other!L11 -> 68426.28 | C11: =Other!M11 -> 69527.77 | D11: =Other!N11 -> 1101.49 | E11: =Other!O11 -> 1.61 | F11: THB
B14: Net Cost | C14: Net Current Value | D14: Net Profit | E14: Percent
A15: Thai Stock | B15: =IF(F2="THB",B2,F2*J2) -> 28800 | C15: =IF(F2="THB",C2,G2*#REF!) -> 35525 | D15: =IF(F2="THB",D2,D2*J2) -> 6725 | E15: =ROUND(100*D15/B15,2) -> 23.35
A16: USA Stock | B16: =IF(F3="THB",B3,B3*J2) -> 67757.6 | C16: =IF(F3="THB",C3,C3*J2) -> 88297.481 | D16: =IF(F3="THB",D3,D3*J2) -> 20539.881 | E16: =ROUND(100*D16/B16,2) -> 30.31
A17: ETF | B17: =IF(F4="THB",B4,B4*J2) -> 18356.504 | C17: =IF(F4="THB",C4,C4*J2) -> 22594.36 | D17: =IF(F4="THB",D4,D4*J2) -> 4237.8558 | E17: =ROUND(100*D17/B17,2) -> 23.09
A18: Fund | B18: =IF(F5="THB",B5,B5*J2) -> 37162.443 | C18: =IF(F5="THB",C5,C5*J2) -> 45957.767 | D18: =IF(F5="THB",D5,D5*J2) -> 8795.3246 | E18: =ROUND(100*D18/B18,2) -> 23.67
A19: Crypto | B19: =IF(F6="THB",B6,B6*J2) -> 7979.9729 | C19: =IF(F6="THB",C6,C6*J2) -> Loading... | D19: =IF(F6="THB",D6,D6*J2) -> Loading... | E19: =ROUND(100*D19/B19,2) -> Loading...
A20: Gold | B20: =IF(F7="THB",B7,B7*J2) -> 14606.017 | C20: =IF(F7="THB",C7,C7*J2) -> 19527.503 | D20: =IF(F7="THB",D7,D7*J2) -> 4964.1636 | E20: =ROUND(100*D20/B20,2) -> 33.99
A21: Insurance | B21: =IF(F8="THB",B8,B8*J3) -> 300000.03 | C21: =IF(F8="THB",C8,C8*J3) -> 300000.03 | D21: =IF(F8="THB",D8,D8*J3) -> 0 | E21: =ROUND(100*D21/B21,2) -> 0
A22: Debenture | B22: =IF(F9="THB",B9,B9*I4) -> 160000 | C22: =IF(F9="THB",C9,C9*I4) -> 160000 | D22: =IF(F9="THB",D9,D9*I4) -> 0 | E22: =ROUND(100*D22/B22,2) -> 0
A23: Bond | B23: =IF(F10="THB",B10,B10*I5) -> 50000 | C23: =IF(F10="THB",C10,C10*I5) -> 50000 | D23: =IF(F10="THB",D10,D10*I5) -> 0 | E23: =ROUND(100*D23/B23,2) -> 0
A24: Provident Fund | B24: =IF(F11="THB",B11,B11*I6) -> 68426.28 | C24: =IF(F11="THB",C11,C11*I6) -> 69527.77 | D24: =IF(F11="THB",D11,D11*I6) -> 1101.49 | E24: =ROUND(100*D24/B24,2) -> 1.61
B28: Net Cost | C28: Net Current Value | D28: Net Profit | E28: Percent
A29: SUM | B29: =SUM(B15:B24) -> 753088.85 | C29: =SUM(C15:C24) -> Loading... | D29: =SUM(D15:D24) -> Loading... | E29: =ROUND((100*C29/B29)-100,2) -> Loading...
A45: Sector | B45: Cost | C45: Current | D45: Percent | F45: Sector | G45: Cost | H45: Current | I45: Percent | K45: Sector | L45: Cost | M45: Current | N45: Percent | P45: Sector | Q45: Cost | R45: Current | S45: Percent | U45: Sector | V45: Cost | W45: Current | X45: Percent
A46: Financials | B46: =SUMIF(THAI_STOCK_SUMMARIZE[Sector],A46,THAI_STOCK_SUMMARIZE[Cost]) -> 28800 | C46: =SUMIF(THAI_STOCK_SUMMARIZE[Sector],A46,THAI_STOCK_SUMMARIZE[Current Value]) -> 35525 | D46: =ROUND((100*C46/B46),2)-100 -> 23.35 | F46: Technology | G46: =SUMIF(USA_STOCK_SUMMARIZE[Sector],F46,USA_STOCK_SUMMARIZE[Cost]) * J2 -> 36126.04 | H46: =SUMIF(USA_STOCK_SUMMARIZE[Sector],F46,USA_STOCK_SUMMARIZE[Current Value])* J2 -> 52160.95 | I46: =ROUND((100*H46/G46),2)-100 -> 44.39 | K46: Technology | L46: =SUMIF(ETF_SUMMARIZE[Sector],K46,ETF_SUMMARIZE[Cost]) * J2 -> 9543.9376 | M46: =SUMIF(ETF_SUMMARIZE[Sector],K46,ETF_SUMMARIZE[Current Value]) * J2 -> 12871.544 | N46: =ROUND((100*M46/L46),2)-100 -> 34.87 | P46: Technology | Q46: =SUMIF(FUND_SUMMARIZE[Sector],P46,FUND_SUMMARIZE[Cost]) -> 7999.9993 | R46: =SUMIF(FUND_SUMMARIZE[Sector],P46,FUND_SUMMARIZE[Current Value]) -> 10285.236 | S46: =ROUND((100*R46/Q46),2)-100 -> 28.57 | U46: Crypto | V46: =B19 -> 7979.9729 | W46: =C19 -> Loading... | X46: =ROUND((100*W46/V46),2)-100 -> Loading...
F47: Consumer | G47: =SUMIF(USA_STOCK_SUMMARIZE[Sector],F47,USA_STOCK_SUMMARIZE[Cost])* J2 -> 11039.937 | H47: =SUMIF(USA_STOCK_SUMMARIZE[Sector],F47,USA_STOCK_SUMMARIZE[Current Value])* J2 -> 11633.9 | I47: =ROUND((100*H47/G47),2)-100 -> 5.38 | K47: S&P | L47: =SUMIF(ETF_SUMMARIZE[Sector],K47,ETF_SUMMARIZE[Cost]) * J2 -> 8812.5664 | M47: =SUMIF(ETF_SUMMARIZE[Sector],K47,ETF_SUMMARIZE[Current Value])* J2 -> 9722.8157 | N47: =ROUND((100*M47/L47),2)-100 -> 10.33 | P47: S&P | Q47: =SUMIF(FUND_SUMMARIZE[Sector],P47,FUND_SUMMARIZE[Cost]) -> 9999.9989 | R47: =SUMIF(FUND_SUMMARIZE[Sector],P47,FUND_SUMMARIZE[Current Value]) -> 12246.687 | S47: =ROUND((100*R47/Q47),2)-100 -> 22.47 | U47: Gold | V47: =B20 -> 14606.017 | W47: =C20 -> 19527.503 | X47: =ROUND((100*W47/V47),2)-100 -> 33.69
F48: Health Care | G48: =SUMIF(USA_STOCK_SUMMARIZE[Sector],F48,USA_STOCK_SUMMARIZE[Cost])* J2 -> 8781.8472 | H48: =SUMIF(USA_STOCK_SUMMARIZE[Sector],F48,USA_STOCK_SUMMARIZE[Current Value])* J2 -> 10822.452 | I48: =ROUND((100*H48/G48),2)-100 -> 23.24 | P48: Korea | Q48: =SUMIF(FUND_SUMMARIZE[Sector],P48,FUND_SUMMARIZE[Cost]) -> 1499.9995 | R48: =SUMIF(FUND_SUMMARIZE[Sector],P48,FUND_SUMMARIZE[Current Value]) -> 2390.5897 | S48: =ROUND((100*R48/Q48),2)-100 -> 59.37
F49: Financials | G49: =SUMIF(USA_STOCK_SUMMARIZE[Sector],F49,USA_STOCK_SUMMARIZE[Cost])* J2 -> 1743.5726 | H49: =SUMIF(USA_STOCK_SUMMARIZE[Sector],F49,USA_STOCK_SUMMARIZE[Current Value])* J2 -> 1722.1858 | I49: =ROUND((100*H49/G49),2)-100 -> -1.23 | P49: Asia | Q49: =SUMIF(FUND_SUMMARIZE[Sector],P49,FUND_SUMMARIZE[Cost]) -> 1999.9996 | R49: =SUMIF(FUND_SUMMARIZE[Sector],P49,FUND_SUMMARIZE[Current Value]) -> 2573.0159 | S49: =ROUND((100*R49/Q49),2)-100 -> 28.65
F50: Defense | G50: =SUMIF(USA_STOCK_SUMMARIZE[Sector],F50,USA_STOCK_SUMMARIZE[Cost])* J2 -> 1006.2276 | H50: =SUMIF(USA_STOCK_SUMMARIZE[Sector],F50,USA_STOCK_SUMMARIZE[Current Value])* J2 -> 1294.419 | I50: =ROUND((100*H50/G50),2)-100 -> 28.64 | P50: Defense | Q50: =SUMIF(FUND_SUMMARIZE[Sector],P50,FUND_SUMMARIZE[Cost]) -> 2499.9992 | R50: =SUMIF(FUND_SUMMARIZE[Sector],P50,FUND_SUMMARIZE[Current Value]) -> 2138.0239 | S50: =ROUND((100*R50/Q50),2)-100 -> -14.48
F51: Space | G51: =SUMIF(USA_STOCK_SUMMARIZE[Sector],F51,USA_STOCK_SUMMARIZE[Cost])* J2 -> 1907.5498 | H51: =SUMIF(USA_STOCK_SUMMARIZE[Sector],F51,USA_STOCK_SUMMARIZE[Current Value])* J2 -> 3925.5771 | I51: =ROUND((100*H51/G51),2)-100 -> 105.79 | P51: Gold | Q51: =SUMIF(FUND_SUMMARIZE[Sector],P51,FUND_SUMMARIZE[Cost]) -> 409.95997 | R51: =SUMIF(FUND_SUMMARIZE[Sector],P51,FUND_SUMMARIZE[Current Value]) -> 349.59599 | S51: =ROUND((100*R51/Q51),2)-100 -> -14.72
F52: Energy | G52: =SUMIF(USA_STOCK_SUMMARIZE[Sector],F52,USA_STOCK_SUMMARIZE[Cost])* J3 -> 2.1461673 | H52: =SUMIF(USA_STOCK_SUMMARIZE[Sector],F52,USA_STOCK_SUMMARIZE[Current Value])* J3 -> 1.9521481 | I52: =ROUND((100*H52/G52),2)-100 -> -9.04 | P52: RareEarth | Q52: =SUMIF(FUND_SUMMARIZE[Sector],P52,FUND_SUMMARIZE[Cost]) -> 2999.9995 | R52: =SUMIF(FUND_SUMMARIZE[Sector],P52,FUND_SUMMARIZE[Current Value]) -> 3212.0486 | S52: =ROUND((100*R52/Q52),2)-100 -> 7.07
P53: Foundation | Q53: =SUMIF(FUND_SUMMARIZE[Sector],P53,FUND_SUMMARIZE[Cost]) -> 2599.5922 | R53: =SUMIF(FUND_SUMMARIZE[Sector],P53,FUND_SUMMARIZE[Current Value]) -> 2782.8299 | S53: =ROUND((100*R53/Q53),2)-100 -> 7.05
P54: Silver | Q54: =SUMIF(FUND_SUMMARIZE[Sector],P54,FUND_SUMMARIZE[Cost]) -> 1874.0723 | R54: =SUMIF(FUND_SUMMARIZE[Sector],P54,FUND_SUMMARIZE[Current Value]) -> 1757.9658 | S54: =ROUND((100*R54/Q54),2)-100 -> -6.2
A59: Sector | B59: Cost | C59: Current | D59: Percent
A60: Financials | B60: =SUMIF(THAI[Sector],A60,THAI[Cost]) + SUMIF(USA[Sector],A60,USA[Cost]) + SUMIF(ETF[Sector],A60,ETF[Cost]) + SUMIF(FUND[Sector],A60,FUND[Cost]) + SUMIF(Other[Sector],A60,Other[Cost]) -> 30543.573 | C60: =SUMIF(THAI[Sector],A60,THAI[Current]) + SUMIF(USA[Sector],A60,USA[Current]) + SUMIF(ETF[Sector],A60,ETF[Current]) + SUMIF(FUND[Sector],A60,FUND[Current]) + SUMIF(Other[Sector],A60,Other[Current]) -> 37247.186 | D60: =ROUND((100*C60/B60),2)-100 -> 21.95
A61: Consumer | B61: =SUMIF(THAI[Sector],A61,THAI[Cost]) + SUMIF(USA[Sector],A61,USA[Cost]) + SUMIF(ETF[Sector],A61,ETF[Cost]) + SUMIF(FUND[Sector],A61,FUND[Cost]) + SUMIF(Other[Sector],A61,Other[Cost]) -> 11039.937 | C61: =SUMIF(THAI[Sector],A61,THAI[Current]) + SUMIF(USA[Sector],A61,USA[Current]) + SUMIF(ETF[Sector],A61,ETF[Current]) + SUMIF(FUND[Sector],A61,FUND[Current]) + SUMIF(Other[Sector],A61,Other[Current]) -> 11633.9 | D61: =ROUND((100*C61/B61),2)-100 -> 5.38
A62: Technology | B62: =SUMIF(THAI[Sector],A62,THAI[Cost]) + SUMIF(USA[Sector],A62,USA[Cost]) + SUMIF(ETF[Sector],A62,ETF[Cost]) + SUMIF(FUND[Sector],A62,FUND[Cost]) + SUMIF(Other[Sector],A62,Other[Cost]) -> 53669.977 | C62: =SUMIF(THAI[Sector],A62,THAI[Current]) + SUMIF(USA[Sector],A62,USA[Current]) + SUMIF(ETF[Sector],A62,ETF[Current]) + SUMIF(FUND[Sector],A62,FUND[Current]) + SUMIF(Other[Sector],A62,Other[Current]) -> 75317.73 | D62: =ROUND((100*C62/B62),2)-100 -> 40.33
A63: Health Care | B63: =SUMIF(THAI[Sector],A63,THAI[Cost]) + SUMIF(USA[Sector],A63,USA[Cost]) + SUMIF(ETF[Sector],A63,ETF[Cost]) + SUMIF(FUND[Sector],A63,FUND[Cost]) + SUMIF(Other[Sector],A63,Other[Cost]) -> 8781.8472 | C63: =SUMIF(THAI[Sector],A63,THAI[Current]) + SUMIF(USA[Sector],A63,USA[Current]) + SUMIF(ETF[Sector],A63,ETF[Current]) + SUMIF(FUND[Sector],A63,FUND[Current]) + SUMIF(Other[Sector],A63,Other[Current]) -> 10822.452 | D63: =ROUND((100*C63/B63),2)-100 -> 23.24
A64: S&P | B64: =SUMIF(THAI[Sector],A64,THAI[Cost]) + SUMIF(USA[Sector],A64,USA[Cost]) + SUMIF(ETF[Sector],A64,ETF[Cost]) + SUMIF(FUND[Sector],A64,FUND[Cost]) + SUMIF(Other[Sector],A64,Other[Cost]) -> 18812.565 | C64: =SUMIF(THAI[Sector],A64,THAI[Current]) + SUMIF(USA[Sector],A64,USA[Current]) + SUMIF(ETF[Sector],A64,ETF[Current]) + SUMIF(FUND[Sector],A64,FUND[Current]) + SUMIF(Other[Sector],A64,Other[Current]) -> 21969.502 | D64: =ROUND((100*C64/B64),2)-100 -> 16.78
...

Sheet Daily
A1: Date | B1: Value
A2: 46072.437 | B2: 640908.2
A3: 46073.362 | B3: 641214.05
A4: 46076.407 | B4: 641635.2
A5: 46077.39 | B5: 641619.92
A6: 46078.402 | B6: =646969.908497947-2500 -> 644469.91
A7: 46079.364 | B7: 647600.58
A8: 46083.541 | B8: 648882.83
A9: 46085.396 | B9: 649071.5
A10: 46086.349 | B10: 652966.02
A11: 46087.361 | B11: 652534.61
A12: 46090.435 | B12: 651747.48
A13: 46091.401 | B13: 651447.03
A14: 46092.442 | B14: 663029.67
A15: 46093.385 | B15: 664339.95
A16: 46094.376 | B16: 663873.78
A17: 46097.409 | B17: 664258.44
A18: 46098.398 | B18: 666280.84
... A59: 46170.379 | B59: 797479.67
